<?xml version="1.0"?>

<robot name="bugv">
    <link name="base_link"/>

    <joint name="base_joint" type="fixed">
        <origin xyz="0 0 0.15" rpy="0 0 0"/>
        <parent link="base_link"/>
        <child link="base_plate"/>
    </joint>

    <link name="base_plate"/>

    <joint name="zed_joint" type="fixed">
        <origin xyz="0.16 0.085 0.02" rpy="0 0 0"/>
        <parent link="base_plate"/>
        <child link="zed_camera_center"/>
    </joint>

    <joint name="lidar_joint" type="fixed">
        <origin xyz="0.105 -0.105 0.03" rpy="0 0 3.1415926536"/>
        <parent link="base_plate"/>
        <child link="lidar_frame"/>
    </joint>

    <link name="lidar_frame"/>

    <joint name="px4_joint" type="fixed">
        <!-- TODO: Check rotation -->
        <origin xyz="-0.08 0 0" rpy="0 0 1.5707963267"/>
        <parent link="base_plate"/>
        <child link="px4_frame"/>
    </joint>

    <link name="px4_frame"/>


    <!-- Imported from zed-ros-wrapper -->

    <link name="zed_camera_center">
        <visual>
            <origin xyz="0 0 0" rpy="0 0 0"/>
            <geometry>
                <mesh filename="package://zed_wrapper/urdf/models/ZEDM.stl" />
            </geometry>
            <material name="light_grey">
                <color rgba="0 0 0 0.9"/>
            </material>
        </visual>
    </link>

    <!-- Left Camera -->
    <joint name="zed_left_camera_joint" type="fixed">
        <parent link="zed_camera_center"/>
        <child link="zed_left_camera_frame"/>
        <origin xyz="0 0.03 0" rpy="0 0 0" />
    </joint>

    <link name="zed_left_camera_frame" />

    <joint name="zed_left_camera_optical_joint" type="fixed">
        <origin xyz="0 0 0" rpy="-1.57079632679 0.0 -1.57079632679"/>
        <parent link="zed_left_camera_frame"/>
        <child link="zed_left_camera_optical_frame"/>
    </joint>

    <link name="zed_left_camera_optical_frame"/>

    <!-- Right Camera -->
    <joint name="zed_right_camera_joint" type="fixed">
        <parent link="zed_camera_center"/>
        <child link="zed_right_camera_frame"/>
        <origin xyz="0 -0.03 0" rpy="0 0 0" />
    </joint>

    <link name="zed_right_camera_frame" />

    <joint name="zed_right_camera_optical_joint" type="fixed">
        <origin xyz="0 0 0" rpy="-1.57079632679 0.0 -1.57079632679"/>
        <parent link="zed_right_camera_frame"/>
        <child link="zed_right_camera_optical_frame"/>
    </joint>

    <link name="zed_right_camera_optical_frame"/>

    <!-- IMU -->    
    <joint name="imu_link_joint" type="floating">
        <parent link="zed_camera_center"/>
        <child link="zed_imu_link"/>
        <origin xyz="0 0 0" rpy="0 0 0" />
    </joint>
    <link name="zed_imu_link" />

</robot>
